Workbook

Sheet Sheet1
A1: Creator | B1: TT Link | D1: Status | F1: Creator | G1: TT Link | H1: Email | I1: Status | K1: Creator | L1: TT Link | M1: Email | N1: Status | P1: Creator | Q1: TT Link | R1: email | S1: Status | U1: Creator | V1: TT Link | X1: Status | Z1: Creator | AA1: TT Link | AC1: Status | AE1: Creator | AF1: TT Link | AH1: Status | AJ1: Creator | AK1: TT Link | AL1: Email | AM1: Status | AO1: Creator | AP1: TT Link | AR1: Status | AT1: Creator | AU1: TT Link | AW1: Status | AY1: Creator | AZ1: TT Link | BB1: Status | BD1: Creator | BE1: TT Link | BF1: email | BG1: Status | BI1: Creator | BJ1: TT Link | BL1: Status
A2: #1: YOU REMEMBER YOU HAVE FREE WILL | F2: #2: food challenge pt2 (where to eat) | K2: #3: MY FAV HIS FAV | P2: #4: ROCK PAPER SCISSORS CHALLENGE | U2: #5: OH WERE U WAITING FOR THAT BOX TO HIT ME | Z2: #6: I'm trying my best | AE2: #7: WHERE?? CHALLENGE | AJ2: #8: HOW MUCH DO I OWE YOU | AO2: #9: how to bait n kidnap me | AT2: #10: sorry we're late, __ throwing a fit | AY2: #11: Holy fkn airball | BD2: #12: Im having sm fun / but we're just doing _ | BI2: #13: target challenge
A3: clairelysse | B3: https://www.tiktok.com/@clairelysse/video/7487790901935279368?is_from_webapp=1&sender_device=pc&web_id=7529868947924829714 | C3: 0129clrc@gmail.com | D3: Consented, Not Included | F3: troubelleee | G3: https://vt.tiktok.com/ZSDS2Rk6b/ | H3: deleted | I3: Consented, Not Included | K3: ravethecrave | L3: https://vt.tiktok.com/ZSAVXhMLG/ | N3: Messaged | P3: adeline.higley | Q3: https://vt.tiktok.com/ZSAVp4tJm/ | S3: Messaged | U3: presello.official | V3: https://vt.tiktok.com/ZSAVskq1w/ | W3: NEW | X3: Consented | Z3: seoul.drop | AA3: https://www.tiktok.com/@seoul.drop/video/7537034038679244062?is_from_webapp=1&sender_device=pc&web_id=7529858502199395858 | AC3: Messaged | AE3: thejulysocial | AF3: https://vt.tiktok.com/ZSAVQLVHV/ | AG3: hello@thejulysocial.com | AH3: Consented | AJ3: kiannady_ | AK3: https://vt.tiktok.com/ZSAVQgjDc/ | AO3: laneigeca | AP3: https://www.tiktok.com/@laneigeca/video/7473887935046110519?is_from_webapp=1&sender_device=pc&web_id=7529868947924829714 | AR3: Messaged | AT3: kiannady_ | AU3: https://www.tiktok.com/@kiannady_/video/7539847364056763655?is_from_webapp=1&sender_device=pc&web_id=7529868947924829714 | AY3: tenten.io | AZ3: https://vt.tiktok.com/ZSAVWJoUX/ | BB3: Messaged | BD3: _cjma | BE3: https://www.tiktok.com/@_cjma/video/7486125299793415446?is_from_webapp=1&sender_device=pc&web_id=7529858502199395858 | BG3: Messaged | BI3: ashandwhit | BJ3: https://www.tiktok.com/@ashandwhit/video/7526376199342312734?is_from_webapp=1&sender_device=pc&web_id=7529868947924829714 | BK3: ashleyandwhitty@gmail.com | BL3: Messaged
A4: thehanniediaries | B4: https://www.tiktok.com/@thehanniediaries/video/7476572873746894122?is_from_webapp=1&sender_device=pc&web_id=7529868947924829714 | C4: ariel@ozlaneagency.com | D4: Messaged | F4: f_fabes | G4: https://vt.tiktok.com/ZSDA5fKct/ | I4: Consented, Not Included | K4: adelinehkim | L4: https://vt.tiktok.com/ZSAVXUhwh/ | M4: adeline@repertoire.us | N4: Messaged | P4: karenchavezzzz | Q4: https://vt.tiktok.com/ZSAVW3B6J/ | S4: Messaged | U4: decathlonph | V4: https://vt.tiktok.com/ZSAVpEWAr/ | X4: Messaged | Z4: jaczdrivein | AA4: https://www.tiktok.com/@jaczdrivein/video/7535961624058858783?is_from_webapp=1&sender_device=pc&web_id=7529858502199395858 | AC4: Messaged | AE4: zigzag.careers | AF4: https://vt.tiktok.com/ZSAVQjUXw/ | AH4: Consented | AJ4: esnyrrr | AK4: https://vt.tiktok.com/ZSAVQcb7P/ | AM4: Messaged | AO4: chatimeph | AP4: https://www.tiktok.com/@chatimeph/video/7476419939264630034?is_from_webapp=1&sender_device=pc&web_id=7529868947924829714 | AR4: Messaged | AT4: samantha.franz | AU4: https://www.tiktok.com/@samantha.franz/video/7539428103076990215?is_from_webapp=1&sender_device=pc&web_id=7529868947924829714 | AW4: Messaged | AY4: bagel_yass.collec | AZ4: https://vt.tiktok.com/ZSAVnQH3F/ | BB4: Consented | BD4: danipenano | BE4: https://www.tiktok.com/@danipenano/video/7514910935954525448?is_from_webapp=1&sender_device=pc&web_id=7529858502199395858 | BG4: Messaged | BI4: kaylarosegibson | BJ4: https://www.tiktok.com/@kaylarosegibson/video/7490299170658503954?is_from_webapp=1&sender_device=pc&web_id=7529868947924829714 | BK4: kaylarose.mgt@gmail.com | BL4: Messaged | BN4: first 5 trends: 1,2,5,7,8 | BO4: https://www.canva.com/design/DAGx6OzNxbU/AHmLLtEl4KHZNdaoA9BrRA/edit
A5: k.wamp | B5: https://www.tiktok.com/@k.wamp/video/7374153120483478827?is_from_webapp=1&sender_device=pc&web_id=7529868947924829714 | C5: gabby@alorasociety.com | D5: Consented | F5: mjhaidel | G5: https://vt.tiktok.com/ZSDA55Va1/ | I5: Consented | K5: sarahh.ongg | L5: https://vt.tiktok.com/ZSAVXMChs/ | M5: sarahhongg23@gmail.com | N5: Messaged | P5: michelle.gacasan | Q5: https://vt.tiktok.com/ZSAVWvYwa/ | S5: Messaged | U5: lpub.jpa | V5: https://vt.tiktok.com/ZSAVsYPTB/ | X5: Consented, Not Included | Z5: ouncecoffee | AA5: https://www.tiktok.com/@ouncecoffee/video/7539578267213303054?is_from_webapp=1&sender_device=pc&web_id=7529858502199395858 | AC5: Messaged | AE5: securitybankcareers | AF5: https://vt.tiktok.com/ZSAVxTjsV/ | AH5: Consented | AJ5: retractables.ph | AK5: https://vt.tiktok.com/ZSAVQtA1Q/ | AM5: Messaged | AO5: theoriginote.ph | AP5: https://www.tiktok.com/@theoriginote.ph/video/7501638878785326344?is_from_webapp=1&sender_device=pc&web_id=7529868947924829714 | AR5: Messaged | AT5: kailady | AU5: https://www.tiktok.com/@kailady/video/7539571671703784711?is_from_webapp=1&sender_device=pc&web_id=7529868947924829714 | AW5: Messaged | AY5: nikishen1025 | AZ5: https://vt.tiktok.com/ZSAVnb5yf/ | BB5: Messaged | BD5: fallinginsociety | BE5: https://www.tiktok.com/@fallinginsociety/video/7525815822405651725?is_from_webapp=1&sender_device=pc&web_id=7529858502199395858 | BG5: Messaged | BI5: abbieherbert | BJ5: https://www.tiktok.com/@abbieherbert/video/6869848082406821125?is_from_webapp=1&sender_device=pc&web_id=7529868947924829714 | BK5: TeamAbbieHerbert@gersh.com | BL5: Messaged | BN5: last 5 tends: 9,10,11,12,13 | BO5: https://www.canva.com/design/DAGzfIt7Tq8/vqD-yMhEBHhBtpt6SEBX6w/edit?ui=eyJIIjp7IkEiOnRydWV9fQ
A6: momshieodille | B6: https://www.tiktok.com/@momshieodille/video/7455549600980634888?is_from_webapp=1&sender_device=pc&web_id=7529868947924829714 | C6: odillekathrina@yahoo.com.ph | D6: Messaged | F6: sukishiyokoo | G6: https://vt.tiktok.com/ZSDA5eTt1/ | I6: Messaged | K6: dailydoseofjos | L6: https://vt.tiktok.com/ZSAVXYVdL/ | M6: josiellisinquiry1@gmail.com | N6: Messaged | P6: bobbylightss01 | Q6: https://vt.tiktok.com/ZSAVWbmJd/ | S6: Messaged | U6: completewedo | V6: https://vt.tiktok.com/ZSAVsDAAW/ | X6: Messaged | Z6: parallaxcoffeelab | AA6: https://www.tiktok.com/@parallaxcoffeelab/video/7535135254219164942?is_from_webapp=1&sender_device=pc&web_id=7529858502199395858 | AC6: Messaged | AE6: parlonph | AF6: https://vt.tiktok.com/ZSAVxsP39/ | AG6: hello@parlon.world | AH6: Messaged | AJ6: sharladavyna | AK6: https://vt.tiktok.com/ZSAVQbsEa/ | AM6: Messaged | AO6: gvnthelabel | AP6: https://www.tiktok.com/@gvnthelabel/video/7507247501431311623?is_from_webapp=1&sender_device=pc&web_id=7529868947924829714 | AR6: Messaged | AT6: kare.bautista | AU6: https://www.tiktok.com/@kare.bautista/video/7530972681924087057?is_from_webapp=1&sender_device=pc&web_id=7529868947924829714 | AW6: Cannot message | AY6: gabriella.sally | AZ6: https://vt.tiktok.com/ZSAVWNaHL/ | BB6: Consented | BD6: mila.magnani | BE6: https://www.tiktok.com/@mila.magnani/video/7484311872817106219?is_from_webapp=1&sender_device=pc&web_id=7529858502199395858 | BG6: Messaged | BI6: simplyivee | BJ6: https://www.tiktok.com/@simplyivee/video/7119152830182690091?is_from_webapp=1&sender_device=pc&web_id=7529868947924829714 | BK6: richard.cooler.mgmt@gmail.com | BL6: Consented, Not Included | BM6: kakaconsent lang
A7: gelamac_ | B7: https://www.tiktok.com/@gelamac_/video/7505661542025743621?is_from_webapp=1&sender_device=pc&web_id=7529868947924829714 | C7: gelamacalalad@gmail.com | D7: Messaged | F7: nvocal123 | G7: https://vt.tiktok.com/ZSDA5w11C/ | I7: Consented | K7: sarahmgaeta | L7: https://vt.tiktok.com/ZSAVXfNAB/ | N7: Messaged | P7: yonmiin | Q7: https://vt.tiktok.com/ZSAV76qKk/ | S7: Messaged | U7: tjtheaterarts | V7: https://vt.tiktok.com/ZSAVsBq2s/ | X7: Messaged | Z7: pjscoffeepensacola | AA7: https://www.tiktok.com/@pjscoffeepensacola/video/7540995085467438349?is_from_webapp=1&sender_device=pc&web_id=7529858502199395858 | AC7: Consented | AE7: kfoandmanders | AF7: https://vt.tiktok.com/ZSAVQJDKc/ | AH7: Messaged | AJ7: aaalxandra | AK7: https://vt.tiktok.com/ZSAVCSdJP/ | AM7: Consented | AO7: spencer.barbosa | AP7: https://www.tiktok.com/@spencer.barbosa/video/7470307135851695366?is_from_webapp=1&sender_device=pc&web_id=7529868947924829714 | AR7: Messaged | AT7: h.akd0g | AU7: https://www.tiktok.com/@h.akd0g/video/7533174782536338695?is_from_webapp=1&sender_device=pc&web_id=7529868947924829714 | AW7: Consented, Not Included | AY7: jackiecamardo | AZ7: https://vt.tiktok.com/ZSAVWAvDL/ | BB7: Messaged | BD7: vivianagalvezz | BE7: https://www.tiktok.com/@vivianagalvezz/video/7518548197925555470?is_from_webapp=1&sender_device=pc&web_id=7529858502199395858 | BG7: Messaged | BI7: aili.likes.adventure | BJ7: https://www.tiktok.com/@aili.likes.adventure/video/7514489015815441707?is_from_webapp=1&sender_device=pc&web_id=7529868947924829714 | BK7: aili@nextintalent.com | BL7: Messaged
A8: ateshi___ | B8: https://www.tiktok.com/@ateshi___/video/7492043988241763639?is_from_webapp=1&sender_device=pc&web_id=7529868947924829714 | D8: Messaged | F8: chobaniflippp | G8: https://vt.tiktok.com/ZSDA53WXK/ | H8: deleted mid study | I8: Consented | K8: caitlinandbecca1 | L8: https://vt.tiktok.com/ZSAVXpPNr/ | N8: Messaged | P8: sha.madiii | Q8: https://vt.tiktok.com/ZSAVWEFv7/ | S8: Messaged | U8: jgworldwide | V8: https://vt.tiktok.com/ZSAVs8Y9Y/ | W8: send results | X8: Consented, Not Included | Z8: nrmitabnita | AA8: https://www.tiktok.com/@nrmitabnita/video/7541541464795319566?is_from_webapp=1&sender_device=pc&web_id=7529858502199395858 | AC8: Messaged | AE8: a.alaynaa_ | AF8: https://vt.tiktok.com/ZSAVx3bEP/ | AH8: Messaged | AJ8: heart_avii | AK8: https://vt.tiktok.com/ZSAVCP7GR/ | AL8: heartavii.contact@gmail.com | AM8: Consented | AO8: kristyna.zamcova | AP8: https://www.tiktok.com/@kristyna.zamcova/video/7473509616186314006?is_from_webapp=1&sender_device=pc&web_id=7529868947924829714 | AR8: Messaged | AT8: awrabriguela | AU8: https://www.tiktok.com/@awrabriguela/video/7542098494325280008?is_from_webapp=1&sender_device=pc&web_id=7529868947924829714 | AW8: Messaged | AY8: allenvert | AZ8: https://vt.tiktok.com/ZSAVWk5C2/ | BB8: Messaged | BD8: provisions.yakima | BE8: https://www.tiktok.com/@provisions.yakima/video/7515117095349259566?is_from_webapp=1&sender_device=pc&web_id=7529858502199395858 | BG8: Messaged | BI8: jessicabaio | BJ8: https://www.tiktok.com/@jessicabaio/video/6869488964395355398?is_from_webapp=1&sender_device=pc&web_id=7529868947924829714 | BL8: Messaged
A9: adv.maris | B9: https://www.tiktok.com/@adv.maris/video/7499286048913050923?is_from_webapp=1&sender_device=pc&web_id=7529868947924829714 | D9: Messaged | F9: just_thaing | G9: https://vt.tiktok.com/ZSDA5Hb7N/ | I9: Messaged | K9: delfinarn | L9: https://vt.tiktok.com/ZSAVXKGVH/ | N9: Messaged | P9: filippogandolfo | Q9: https://vt.tiktok.com/ZSAV7Bp8T/ | S9: Messaged | U9: ubckwave | V9: https://vt.tiktok.com/ZSAVsHpt1/ | X9: Consented | Z9: darlinsdinertx | AA9: https://www.tiktok.com/@darlinsdinertx/video/7541796609747717406?is_from_webapp=1&sender_device=pc&web_id=7529858502199395858 | AC9: Consented | AE9: shesxin | AF9: https://vt.tiktok.com/ZSAVQNo8E/ | AH9: Messaged | AJ9: casey.dasilva | AK9: https://vt.tiktok.com/ZSAVCStQf/ | AL9: inquiries.caseydasilva@gmail.com | AM9: Messaged | AO9: nausikamalshi | AP9: https://www.tiktok.com/@nausikamalshi/video/7485068513783106822?is_from_webapp=1&sender_device=pc&web_id=7529868947924829714 | AR9: Messaged | AT9: russcojarvina_ | AU9: https://www.tiktok.com/@russcojarvina_/video/7532056769934249224?is_from_webapp=1&sender_device=pc&web_id=7529868947924829714 | AW9: Messaged | AY9: sophia_hg1 | AZ9: https://vt.tiktok.com/ZSAVWrcRD/ | BB9: Consented | BD9: flywithamyangela | BE9: https://www.tiktok.com/@flywithamyangela/video/7527388566901542166?is_from_webapp=1&sender_device=pc&web_id=7529858502199395858 | BG9: Messaged | BI9: jrandblessie | BJ9: https://www.tiktok.com/@jrandblessie/video/7471463047949733162?is_from_webapp=1&sender_device=pc&web_id=7529868947924829714 | BL9: Messaged
A10: paige.braude | B10: https://www.tiktok.com/@paige.braude/video/7506666091163356462?is_from_webapp=1&sender_device=pc&web_id=7529868947924829714 | C10: paigebraude@gmail.com | D10: Consented, Not Included | F10: heytrishadae | G10: https://vt.tiktok.com/ZSDA5aWvP/ | I10: Messaged | K10: abigailcraig | L10: https://vt.tiktok.com/ZSAVXKax1/ | M10: abigailgcraigg@gmail.com | N10: Messaged | P10: 1.best.memes | Q10: https://vt.tiktok.com/ZSAV7Dmvn/ | S10: Messaged | U10: fintech.calgary | V10: https://vt.tiktok.com/ZSAVsHPde/ | W10: NEW | X10: Consented | Z10: caringtonarms_ | AA10: https://www.tiktok.com/@caringtonarms_/video/7540359115848125718?is_from_webapp=1&sender_device=pc&web_id=7529858502199395858 | AB10: ig | AC10: Messaged | AE10: belle__wilson | AF10: https://vt.tiktok.com/ZSAVxcYhJ/ | AG10: attyjcd@gmail.com | AH10: Messaged | AJ10: cocoriroo | AK10: https://vt.tiktok.com/ZSAVCUQgR/ | AM10: Consented | AO10: klaileaj | AP10: https://www.tiktok.com/@klaileaj/video/7470933959812189462?is_from_webapp=1&sender_device=pc&web_id=7529868947924829714 | AR10: Messaged | AT10: daisiesfolife | AU10: https://www.tiktok.com/@daisiesfolife/video/7531263426715258126?is_from_webapp=1&sender_device=pc&web_id=7529868947924829714 | AW10: Messaged | AY10: erinruizart | AZ10: https://vt.tiktok.com/ZSAVWr7Sv/ | BB10: Messaged | BD10: weirdsortanot | BE10: https://www.tiktok.com/@weirdsortanot/video/7480305481173716270?is_from_webapp=1&sender_device=pc&web_id=7529858502199395858 | BG10: Messaged | BI10: _addirobertson_ | BJ10: https://www.tiktok.com/@_addirobertson_/video/7471383932672511278?is_from_webapp=1&sender_device=pc&web_id=7529868947924829714 | BK10: addirobertson6@gmail.com | BL10: Messaged
A11: maligoshik | B11: https://www.tiktok.com/@maligoshik/video/7331439871468375302?is_from_webapp=1&sender_device=pc&web_id=7529868947924829714 | C11: hello@maligoshik.com | D11: Messaged | F11: aa.nomnoms | G11: https://vt.tiktok.com/ZSDAaF6f2/ | I11: Consented, Not Included | K11: laurwholooks4 | L11: https://vt.tiktok.com/ZSAVXVSTd/ | N11: Messaged | P11: kassyymiraa | Q11: https://vt.tiktok.com/ZSAV7MmfB/ | S11: Messaged | U11: fitchburgstate | V11: https://vt.tiktok.com/ZSAVsCtao/ | X11: Messaged | Z11: strangebrewcoffeein | AA11: https://www.tiktok.com/@strangebrewcoffeein/video/7536267754811313439?is_from_webapp=1&sender_device=pc&web_id=7529858502199395858 | AC11: Messaged | AE11: notnikady | AF11: https://vt.tiktok.com/ZSAVQdPGx/ | AG11: annikamdy@gmail.com | AH11: Messaged | AJ11: ellaaa.killa | AK11: https://vt.tiktok.com/ZSAVCFGDo/ | AM11: Messaged | AO11: chimamalko | AP11: https://www.tiktok.com/@chimamalko/video/7467746763433217326?is_from_webapp=1&sender_device=pc&web_id=7529868947924829714 | AR11: Messaged | AT11: kiody__ | AU11: https://www.tiktok.com/@kiody__/video/7535688484657433873?is_from_webapp=1&sender_device=pc&web_id=7529868947924829714 | AW11: Messaged | AY11: alyyyjn_ | AZ11: https://vt.tiktok.com/ZSAVWjdjD/ | BB11: Messaged | BD11: andreiiiii3636 | BE11: https://www.tiktok.com/@andreiiiii3636/video/7519020169025375495?is_from_webapp=1&sender_device=pc&web_id=7529858502199395858 | BG11: Consented | BI11: kaylarosegibson | BJ11: https://www.tiktok.com/@kaylarosegibson/video/7498116646087724306?is_from_webapp=1&sender_device=pc&web_id=7529868947924829714 | BL11: Messaged | BQ11: List of trends
A12: yas.francis | B12: https://www.tiktok.com/@yas.francis/video/7474017420135501102?is_from_webapp=1&sender_device=pc&web_id=7529868947924829714 | C12: yfrancis2022@gmail.com | D12: Messaged | F12: _joemommaaa | G12: https://vt.tiktok.com/ZSDAae8Gr/ | I12: Messaged | K12: mercedes.pomerleau | L12: https://vt.tiktok.com/ZSAVXQn7s/ | N12: Messaged | P12: snvoid | Q12: https://vt.tiktok.com/ZSAV7Sn6F/ | S12: Messaged | U12: purplebugph | V12: https://vt.tiktok.com/ZSAVsng9V/ | X12: Messaged | Z12: zimo.bakery.and.c | AA12: https://www.tiktok.com/@zimo.bakery.and.c/video/7541134698056011021?is_from_webapp=1&sender_device=pc&web_id=7529858502199395858 | AC12: Messaged | AE12: muktiorganics | AF12: https://vt.tiktok.com/ZSAVxvpK7/ | AH12: Messaged | AJ12: _pottea | AK12: https://vt.tiktok.com/ZSAVV9dhq/ | AM12: Consented | AO12: rarebreezy_shoes | AP12: https://www.tiktok.com/@rarebreezy_shoes/video/7472976795629931784?is_from_webapp=1&sender_device=pc&web_id=7529868947924829714 | AR12: Messaged | AT12: eriaaa_m | AU12: https://www.tiktok.com/@eriaaa_m/video/7541681928659848456?is_from_webapp=1&sender_device=pc&web_id=7529868947924829714 | AW12: Messaged | AY12: noa..marin | AZ12: https://vt.tiktok.com/ZSAVWaXes/ | BB12: Messaged | BD12: angelicadchvzz | BE12: https://www.tiktok.com/@angelicadchvzz/video/7477958483552259336?is_from_webapp=1&sender_device=pc&web_id=7529858502199395858 | BG12: Consented | BI12: kaylarosegibson | BJ12: https://www.tiktok.com/@kaylarosegibson/video/7482502968000957704?is_from_webapp=1&sender_device=pc&web_id=7529868947924829714 | BL12: Messaged | BQ12: you remember you have free will | BR12: =D150 -> 10
A13: griffith_uni | B13: https://www.tiktok.com/@griffith_uni/video/7465839078433492232?is_from_webapp=1&sender_device=pc&web_id=7529868947924829714 | D13: Messaged | F13: _zxick | G13: https://vt.tiktok.com/ZSDAaL3nK/ | I13: Consented | K13: claraspannaus | L13: https://vt.tiktok.com/ZSAVXVmG2/ | N13: Messaged | P13: krist..iana | Q13: https://vt.tiktok.com/ZSAV7mGK1/ | S13: Messaged | U13: cleancorpau | V13: https://vt.tiktok.com/ZSAVs4moA/ | W13: i dont rlly like pero pwede | X13: Consented | Z13: club29decherd | AA13: https://www.tiktok.com/@club29decherd/video/7535116470519336222?is_from_webapp=1&sender_device=pc&web_id=7529858502199395858 | AC13: Messaged | AE13: amo_thobye | AF13: https://vt.tiktok.com/ZSAVQLn9k/ | AG13: amothobye@gmail.com | AH13: Consented | AJ13: silly.monse | AK13: https://vt.tiktok.com/ZSAVCSvoH/ | AM13: Messaged | AO13: kristyna.zamcova | AP13: https://www.tiktok.com/@kristyna.zamcova/video/7473522329037982998?is_from_webapp=1&sender_device=pc&web_id=7529868947924829714 | AR13: Messaged | AT13: jellyaace._ | AU13: https://www.tiktok.com/@jellyaace._/video/7535085676858068231?is_from_webapp=1&sender_device=pc&web_id=7529868947924829714 | AW13: Consented | AY13: kristinagenau | AZ13: https://vt.tiktok.com/ZSAVWdJg6/ | BB13: Messaged | BD13: pladalp_ | BE13: https://www.tiktok.com/@pladalp_/video/7541651942443994423?is_from_webapp=1&sender_device=pc&web_id=7529858502199395858 | BG13: Cannot message | BI13: kaylarosegibson | BJ13: https://www.tiktok.com/@kaylarosegibson/video/7494780860902690055?is_from_webapp=1&sender_device=pc&web_id=7529868947924829714 | BL13: Messaged | BQ13: food challenge | BR13: =I150 -> 10
A14: joeando | B14: https://www.tiktok.com/@joeando/video/7165667445594934574?is_from_webapp=1&sender_device=pc&web_id=7529868947924829714 | D14: Messaged | F14: teoandsheks | G14: https://vt.tiktok.com/ZSDA5ENAG/ | I14: Messaged | K14: fallingfromgrace | L14: https://vt.tiktok.com/ZSAVXsfmc/ | N14: Consented | P14: jamsones_2 | Q14: https://vt.tiktok.com/ZSAV7X3Eq/ | S14: Messaged | U14: legacytolifted | V14: https://vt.tiktok.com/ZSAVsV2E2/ | X14: Messaged | Z14: surfshackcastlerock | AA14: https://www.tiktok.com/@surfshackcastlerock/video/7535841470595730710?is_from_webapp=1&sender_device=pc&web_id=7529858502199395858 | AB14: ig | AC14: Consented | AE14: allexadalessio | AF14: https://vt.tiktok.com/ZSAVxKDNc/ | AG14: https://www.instagram.com/allexadalessio/ | AH14: Messaged | AJ14: nathandegrn | AK14: https://vt.tiktok.com/ZSAVCNK7U/ | AM14: Messaged | AO14: mollyatmidnight | AP14: https://www.tiktok.com/@mollyatmidnight/video/7473172343464987926?is_from_webapp=1&sender_device=pc&web_id=7529868947924829714 | AR14: Messaged | AT14: bitanywatnat | AU14: https://www.tiktok.com/@bitanywatnat/video/7540573802564979975?is_from_webapp=1&sender_device=pc&web_id=7529868947924829714 | AW14: Messaged | AY14: yoyo.spaces | AZ14: https://vt.tiktok.com/ZSAVWHFHG/ | BB14: Messaged | BD14: clarrengggg | BE14: https://www.tiktok.com/@clarrengggg/video/7519760474582322450?is_from_webapp=1&sender_device=pc&web_id=7529858502199395858 | BG14: Messaged | BI14: thequistfamily | BJ14: https://www.tiktok.com/@thequistfamily/video/7466983735309913390?is_from_webapp=1&sender_device=pc&web_id=7529868947924829714 | BK14: CourtneyandAlexQuist@gmail.com | BL14: Messaged | BQ14: my fave, his fave | BR14: =N150 -> 6
A15: victoriaxmariah | B15: https://www.tiktok.com/@victoriaxmariah/video/7456976760916266286?is_from_webapp=1&sender_device=pc&web_id=7529868947924829714 | D15: Messaged | F15: inigojap | G15: https://vt.tiktok.com/ZSDAaRqGM/ | I15: Consented | K15: aylafr3din | L15: https://vt.tiktok.com/ZSAVX4Rst/ | M15: aylafredin@gmail.com | N15: Messaged | P15: itsdiamonddust | Q15: https://vt.tiktok.com/ZSAV7mLmW/ | S15: Messaged | U15: hydrogenfitness | V15: https://vt.tiktok.com/ZSAVsoxbY/ | X15: Messaged | Z15: mjscoffeebar | AA15: https://www.tiktok.com/@mjscoffeebar/video/7539950568786332934?is_from_webapp=1&sender_device=pc&web_id=7529858502199395858 | AC15: Messaged | AE15: alyssanaka | AF15: https://vt.tiktok.com/ZSAVQYq2y/ | AG15: AlyssaNakaSilver@gmail.com | AH15: Messaged | AJ15: douknowkent | AK15: https://vt.tiktok.com/ZSAVCuuyX/ | AM15: Consented | AO15: skylar_diecast | AP15: https://www.tiktok.com/@skylar_diecast/video/7479268371700223240?is_from_webapp=1&sender_device=pc&web_id=7529868947924829714 | AR15: Consented | AT15: louiemrn | AU15: https://www.tiktok.com/@louiemrn/video/7534307314237443335?is_from_webapp=1&sender_device=pc&web_id=7529868947924829714 | AW15: Consented | AY15: auv.n.jack | AZ15: https://www.tiktok.com/@auv.n.jack/video/7519508979634949431?is_from_webapp=1&sender_device=pc&web_id=7529858502199395858 | BB15: Messaged | BD15: migmiggymig | BE15: https://www.tiktok.com/@migmiggymig/video/7487622680309419286?is_from_webapp=1&sender_device=pc&web_id=7529858502199395858 | BG15: Consented | BI15: aubrayandbailey | BJ15: https://www.tiktok.com/@aubrayandbailey/video/7277775628546395422?is_from_webapp=1&sender_device=pc&web_id=7529868947924829714 | BK15: collabs@aubrayandbailey.com | BL15: Messaged | BQ15: rock paper scissors food challenge | BR15: =S150 -> 7
A16: volkswagensg | B16: https://www.tiktok.com/@volkswagensg/video/7476028960699206930?is_from_webapp=1&sender_device=pc&web_id=7529868947924829714 | D16: Messaged | F16: gl_jz | G16: https://vt.tiktok.com/ZSDA5EBqo/ | I16: Messaged | K16: isabelletrotter | L16: https://vt.tiktok.com/ZSAVXueuC/ | M16: isabellegtrotter@gmail.com | N16: Messaged | P16: ellexismoss | Q16: https://vt.tiktok.com/ZSAV7xjHS/ | S16: Messaged | U16: pixiogaming | V16: https://vt.tiktok.com/ZSAqcprMf/ | X16: Consented | Z16: 278nutrition | AA16: https://www.tiktok.com/@278nutrition/video/7538411940561898782?is_from_webapp=1&sender_device=pc&web_id=7529858502199395858 | AC16: Messaged | AE16: kaemia | AF16: https://vt.tiktok.com/ZSAVxEF9R/ | AH16: Did not consent | AJ16: jessicafakhri | AK16: https://vt.tiktok.com/ZSAVCrFvc/ | AM16: Messaged | AO16: anastasia.c.chronicles | AP16: https://www.tiktok.com/@anastasia.c.chronicles/video/7468981725352201505?is_from_webapp=1&sender_device=pc&web_id=7529868947924829714 | AR16: Messaged | AT16: andweaso | AU16: https://www.tiktok.com/@andweaso/video/7532105050844417288?is_from_webapp=1&sender_device=pc&web_id=7529868947924829714 | AW16: Messaged | AY16: mikaylademaiterr | AZ16: https://www.tiktok.com/@mikaylademaiterr/video/7509206684959608070?is_from_webapp=1&sender_device=pc&web_id=7529858502199395858 | BB16: Messaged | BD16: _marghsss | BE16: https://www.tiktok.com/@_marghsss/video/7512255755878223146?is_from_webapp=1&sender_device=pc&web_id=7529858502199395858 | BG16: Messaged | BI16: andreaandlewis | BJ16: https://www.tiktok.com/@andreaandlewis/video/6870581248448908549?is_from_webapp=1&sender_device=pc&web_id=7529868947924829714 | BK16: lewisandreaofficial@gmail.com | BL16: Messaged | BQ16: oh were u waiting for that box to hit me? | BR16: =X64 -> 10
A17: anna.antonje | B17: https://www.tiktok.com/@anna.antonje/video/7443465454921846038?is_from_webapp=1&sender_device=pc&web_id=7529868947924829714 | D17: Messaged | F17: thisjenngirl | G17: https://vt.tiktok.com/ZSDAa4jsr/ | I17: Messaged | K17: sam_vlogzz | L17: https://vt.tiktok.com/ZSAVX7DYb/ | N17: Messaged | P17: teachermrsthomas | Q17: https://vt.tiktok.com/ZSAV7utqK/ | S17: Messaged | U17: soocialhub | V17: https://vt.tiktok.com/ZSAqcw5Kw/ | X17: Messaged | Z17: acaidelightok | AA17: https://www.tiktok.com/@acaidelightok/video/7535672114477681950?is_from_webapp=1&sender_device=pc&web_id=7529858502199395858 | AC17: Messaged | AE17: dinoraan | AF17: https://vt.tiktok.com/ZSAVQ4PXL/ | AG17: dinoranurillaeva@gmail.com | AH17: Messaged | AJ17: kiannady_ | AK17: https://vt.tiktok.com/ZSAVCFPqD/ | AM17: Messaged | AO17: rebisco.ph | AP17: https://www.tiktok.com/@rebisco.ph/video/7473722343882247442?is_from_webapp=1&sender_device=pc&web_id=7529868947924829714 | AR17: Messaged | AT17: nacho.bizz | AU17: https://www.tiktok.com/@nacho.bizz/video/7541698829935054088?is_from_webapp=1&sender_device=pc&web_id=7529868947924829714 | AW17: Consented | AY17: biscuitaddict06 | AZ17: https://www.tiktok.com/@biscuitaddict06/video/7516551249475456263?is_from_webapp=1&sender_device=pc&web_id=7529858502199395858 | BB17: Messaged | BD17: danjanine | BE17: https://www.tiktok.com/@danjanine/video/7519978917613079821?is_from_webapp=1&sender_device=pc&web_id=7529858502199395858 | BG17: Messaged | BI17: aileenchristineee | BJ17: https://www.tiktok.com/@aileenchristineee/video/6867743685199596806?is_from_webapp=1&sender_device=pc&web_id=7529868947924829714 | BL17: Messaged | BQ17: this looks like it was made by a 5 year old, im trying my best | BR17: =AC64 -> 4
A18: ambardriscoll | B18: https://www.tiktok.com/@ambardriscoll/video/7503566266301582594?is_from_webapp=1&sender_device=pc&web_id=7529868947924829714 | C18: ambar@mvetalent.com | D18: Messaged | F18: clairealexistiu | G18: https://vt.tiktok.com/ZSDAaX7TN/ | I18: Consented | K18: meganjspams | L18: https://vt.tiktok.com/ZSAVX3YCK/ | N18: Messaged | P18: meganmarie800 | Q18: https://vt.tiktok.com/ZSAqTeheg/ | S18: Messaged | U18: parkplacernv | V18: https://vt.tiktok.com/ZSAqc7arm/ | W18: leasing@parkplaceatreno.com | X18: Consented, Not Included | Z18: eastfield.farm.plants | AA18: https://www.tiktok.com/@eastfield.farm.plants/video/7542576997017390358?is_from_webapp=1&sender_device=pc&web_id=7529858502199395858 | AB18: ig | AC18: Messaged | AE18: glossmoves | AF18: https://vt.tiktok.com/ZSAVQjnwA/ | AH18: Messaged | AJ18: lincandcanyon | AK18: https://vt.tiktok.com/ZSAVCsYk6/ | AL18: lincandcanyon@gb-dm.com | AM18: Messaged | AO18: gabyy.library | AP18: https://www.tiktok.com/@gabyy.library/video/7474052998965005614?is_from_webapp=1&sender_device=pc&web_id=7529868947924829714 | AR18: Messaged | AT18: nicoleeeyxx | AU18: https://www.tiktok.com/@nicoleeeyxx/video/7533826466778254610?is_from_webapp=1&sender_device=pc&web_id=7529868947924829714 | AW18: Messaged | AY18: .vienna.s | AZ18: https://www.tiktok.com/@.vienna.s/video/7511759087261158678?is_from_webapp=1&sender_device=pc&web_id=7529858502199395858 | BB18: Messaged | BD18: evzeca | BE18: https://www.tiktok.com/@evzeca/video/7539581917465677070?is_from_webapp=1&sender_device=pc&web_id=7529858502199395858 | BG18: Messaged | BI18: matt_and_abby | BJ18: https://www.tiktok.com/@matt_and_abby/video/6869099288610229509?is_from_webapp=1&sender_device=pc&web_id=7529868947924829714 | BK18: business@mattandabby.co | BL18: Messaged | BN18: RED ------> | BO18: Has several videos we used | BQ18: WHERE?? | BR18: =AH64 -> 10
A19: samanthaysabel.co | B19: https://www.tiktok.com/@samanthaysabel.co/video/7502777453358746888?is_from_webapp=1&sender_device=pc&web_id=7529868947924829714 | D19: Messaged | F19: allisonmrey | G19: https://vt.tiktok.com/ZSDAay8k1/ | I19: Messaged | K19: zeliha_clark | L19: https://vt.tiktok.com/ZSAVXQjAj/ | M19: zelihaclark@ddaglobal.com | N19: Messaged | P19: nonsensewit.nixx | Q19: https://vt.tiktok.com/ZSAq3GpsG/ | S19: Messaged | U19: shaker.auto.group | V19: https://vt.tiktok.com/ZSAq3AAUy/ | X19: Messaged | Z19: menomonie.market | AA19: https://www.tiktok.com/@menomonie.market/video/7536306811540884767?is_from_webapp=1&sender_device=pc&web_id=7529858502199395858 | AC19: Messaged | AE19: karimilanivlogs | AF19: https://vt.tiktok.com/ZSAVQ6pxV/ | AG19: https://www.instagram.com/kari_milani | AH19: Messaged | AJ19: kennyand_thejets | AK19: https://vt.tiktok.com/ZSAVCwmHN/ | AM19: Messaged | AO19: fitsbymon | AP19: https://www.tiktok.com/@fitsbymon/video/7474664201806499094?is_from_webapp=1&sender_device=pc&web_id=7529868947924829714 | AR19: Messaged | AT19: gmaregionaltv_ | AU19: https://www.tiktok.com/@gmaregionaltv_/video/7543181685425245447?is_from_webapp=1&sender_device=pc&web_id=7529868947924829714 | AW19: Messaged | AY19: theexerciseengineer | AZ19: https://www.tiktok.com/@theexerciseengineer/video/7508996910724795670?is_from_webapp=1&sender_device=pc&web_id=7529858502199395858 | BB19: Cannot message | BD19: jun1k1t | BE19: https://www.tiktok.com/@jun1k1t/video/7514516690030316843?is_from_webapp=1&sender_device=pc&web_id=7529858502199395858 | BG19: Messaged | BI19: arissaadams | BJ19: https://www.tiktok.com/@arissaadams/video/7163684708839378182?is_from_webapp=1&sender_device=pc&web_id=7529868947924829714 | BK19: adamsarissa15@gmail.com | BL19: Messaged | BQ19: how much do i owe u | BR19: =AM64 -> 10
A20: love.maceee | B20: https://www.tiktok.com/@love.maceee/video/7516108400787295495?is_from_webapp=1&sender_device=pc&web_id=7529868947924829714 | D20: Consented | F20: thecabrerafam | G20: https://vt.tiktok.com/ZSDAaurWa/ | I20: Messaged | K20: kev_sndvl | L20: https://vt.tiktok.com/ZSAsRwXpV/ | N20: Consented | P20: naye.martinezz | Q20: https://vt.tiktok.com/ZSAq3wcrh/ | S20: Messaged | U20: lightartcreators | V20: https://vt.tiktok.com/ZSAq368EC/ | X20: Messaged | Z20: pinkdoorhgt | AA20: https://www.tiktok.com/@pinkdoorhgt/video/7539871335816662294?is_from_webapp=1&sender_device=pc&web_id=7529858502199395858 | AB20: ig | AC20: Messaged | AE20: sophiesticated618 | AF20: https://vt.tiktok.com/ZSAV47CrT/ | AG20: attyjcd@gmail.com | AH20: Messaged | AJ20: yapi_so | AK20: https://vt.tiktok.com/ZSAV45FDC/ | AM20: Messaged | AO20: mynameisadrienne | AP20: https://www.tiktok.com/@mynameisadrienne/video/7471042913544195374?is_from_webapp=1&sender_device=pc&web_id=7529868947924829714 | AR20: Consented | AT20: yzhakane | AU20: https://www.tiktok.com/@yzhakane/video/7541302079588011272?is_from_webapp=1&sender_device=pc&web_id=7529868947924829714 | AW20: Consented | AY20: fern.sthetics | AZ20: https://www.tiktok.com/@fern.sthetics/video/7509130988149017864?is_from_webapp=1&sender_device=pc&web_id=7529858502199395858 | BB20: Messaged | BD20: austinandhaven5 | BE20: https://www.tiktok.com/@austinandhaven5/video/7522243782847368479?is_from_webapp=1&sender_device=pc&web_id=7529858502199395858 | BG20: Messaged | BI20: laura88lee | BJ20: https://www.tiktok.com/@laura88lee/video/7325856822592539934?is_from_webapp=1&sender_device=pc&web_id=7529868947924829714 | BL20: Messaged | BQ20: how to kidnap me | BR20: =AR136 -> 10
A21: lifeaszeph | B21: https://www.tiktok.com/@lifeaszeph/video/7451788412312489246?is_from_webapp=1&sender_device=pc&web_id=7529868947924829714 | C21: Zephriseorfall@gmail | D21: Messaged | F21: thekadproject | G21: https://vt.tiktok.com/ZSDAaqREC/ | I21: Messaged | K21: its_justnatt | L21: https://vt.tiktok.com/ZSAVq5nkt/ | M21: nataliefoo02@gmail.com | N21: Did not consent | P21: munchies_78 | Q21: https://vt.tiktok.com/ZSAqT1G8X/ | S21: Messaged | U21: eastern.market.canton | V21: https://vt.tiktok.com/ZSAq3ADaV/ | X21: Messaged | Z21: palm.coffee.lounge | AA21: https://www.tiktok.com/@palm.coffee.lounge/video/7544037628421704982?is_from_webapp=1&sender_device=pc&web_id=7529858502199395858 | AB21: ig | AC21: Messaged | AE21: taylor_zaydie | AF21: https://vt.tiktok.com/ZSAVVSQmg/ | AH21: Messaged | AJ21: rip_on_heaven | AK21: https://vt.tiktok.com/ZSAVVhMjv/ | AL21: ig | AM21: Cannot message | AO21: sksnnbwe | AP21: https://www.tiktok.com/@sksnnbwe/video/7466277657542511915?is_from_webapp=1&sender_device=pc&web_id=7529868947924829714 | AR21: Messaged | AT21: microwavablep0pcorn | AU21: https://www.tiktok.com/@microwavablep0pcorn/video/7528764177473719570?is_from_webapp=1&sender_device=pc&web_id=7529868947924829714 | AW21: Consented | AY21: somebody_you_fw | AZ21: https://www.tiktok.com/@somebody_you_fw/video/7538996939266755854?is_from_webapp=1&sender_device=pc&web_id=7529858502199395858 | BB21: Messaged | BD21: katie.bri25 | BE21: https://www.tiktok.com/@katie.bri25/video/7536026187391356215?is_from_webapp=1&sender_device=pc&web_id=7529858502199395858 | BG21: Messaged | BI21: _thescottfamily | BJ21: https://www.tiktok.com/@_thescottfamily/video/6870273964351016198?is_from_webapp=1&sender_device=pc&web_id=7529868947924829714 | BK21: TeamRogerandTalia@gersh.com | BL21: Messaged | BQ21: sorry we're late, __ was throwing a fit | BR21: =AW62 -> 10
A22: notconstancezhang93 | B22: https://www.tiktok.com/@notconstancezhang93/video/7369633099023519018?is_from_webapp=1&sender_device=pc&web_id=7529868947924829714 | C22: Constancezqz@gmail.com | D22: Messaged | F22: marcodaos | G22: https://vt.tiktok.com/ZSDAa4K5o/ | I22: Messaged | K22: brynnguymon | L22: https://vt.tiktok.com/ZSAVbJx7m/ | M22: brynnguymon@palettemgmt.com | N22: Messaged | P22: _alyviagrace | Q22: https://vt.tiktok.com/ZSAq3qpoj/ | S22: Messaged | U22: solugenixdr | V22: https://vt.tiktok.com/ZSAq3yXtd/ | X22: Messaged | Z22: cakeboutiquenj | AA22: https://www.tiktok.com/@cakeboutiquenj/video/7539654471010372919?is_from_webapp=1&sender_device=pc&web_id=7529858502199395858 | AC22: Did not consent | AE22: imanisallahh | AF22: https://vt.tiktok.com/ZSAVVsfK9/ | AH22: Messaged | AJ22: kikaydinsay_ | AK22: https://vt.tiktok.com/ZSAVVaq7R/ | AL22: kikaydinsay@gmail.com | AM22: Consented | AO22: leahgiggle | AP22: https://www.tiktok.com/@leahgiggle/video/7520771574207712543?is_from_webapp=1&sender_device=pc&web_id=7529868947924829714 | AR22: Messaged | AT22: chynnachuaa | AU22: https://www.tiktok.com/@chynnachuaa/video/7536834940202224904?is_from_webapp=1&sender_device=pc&web_id=7529868947924829714 | AW22: Messaged | AY22: 15hourss | AZ22: https://www.tiktok.com/@15hourrss/video/7511927587984248107?is_from_webapp=1&sender_device=pc&web_id=7529858502199395858 | BB22: Cannot message | BD22: themorrisfambam | BE22: https://www.tiktok.com/@themorrisfambam/video/7507492909160074526?is_from_webapp=1&sender_device=pc&web_id=7529858502199395858 | BG22: Messaged | BI22: brittany.xavier | BJ22: https://www.tiktok.com/@brittany.xavier/video/6909256535436692737?is_from_webapp=1&sender_device=pc&web_id=7529868947924829714 | BL22: Messaged | BQ22: holy airball | BR22: =BB62 -> 10
A23: nikki.gott | B23: https://www.tiktok.com/@nikki.gott/video/7538926247401868574?is_from_webapp=1&sender_device=pc&web_id=7529868947924829714 | C23: nikkigottcent@gmail.com | D23: Messaged | F23: iam.maks | G23: https://vt.tiktok.com/ZSDAaP3KN/ | I23: Messaged | K23: aneliesetannoui | L23: https://vt.tiktok.com/ZSAVbe6os/ | M23: aneliese.tannourji@outlook.com | N23: Messaged | P23: daisypitts | Q23: https://vt.tiktok.com/ZSAqTuqNX/ | S23: Messaged | U23: sdhumanesociety | V23: https://vt.tiktok.com/ZSDRb3Mpo/ | X23: Consented | Z23: cupbop | AA23: https://www.tiktok.com/@cupbop/video/7541560963426716942?is_from_webapp=1&sender_device=pc&web_id=7529868947924829714 | AC23: Messaged | AE23: taniaturdean | AF23: https://www.tiktok.com/@taniaturdean/video/7473452610926693654?is_from_webapp=1&sender_device=pc&web_id=7534997804440471048 | AH23: Messaged | AJ23: nattarts | AK23: https://vt.tiktok.com/ZSAvpuS1F/ | AM23: Consented | AO23: its.sofii.vb | AP23: https://www.tiktok.com/@its.sofii.vb/video/7471775493516283191?is_from_webapp=1&sender_device=pc&web_id=7529868947924829714 | AR23: Messaged | AT23: paige_go | AU23: https://www.tiktok.com/@paige_go/video/7533923640908188946?is_from_webapp=1&sender_device=pc&web_id=7529868947924829714 | AW23: Messaged | AY23: mommy.dans | AZ23: https://www.tiktok.com/@mommy.dans/video/7517917239304015121?is_from_webapp=1&sender_device=pc&web_id=7529868947924829714 | BB23: Messaged | BD23: urmrselastyles | BE23: https://www.tiktok.com/@urmrselastyles/video/7545122823392546055?is_from_webapp=1&sender_device=pc&web_id=7529858502199395858 | BG23: Messaged | BI23: brittany.xavier | BJ23: https://www.tiktok.com/@brittany.xavier/video/6902938334113303809?is_from_webapp=1&sender_device=pc&web_id=7529868947924829714 | BL23: Messaged | BQ23: im having sm fun/ but we're just doing __ / but we're doing __ together | BR23: =BG199 -> 10
A24: hailzngrace | B24: https://www.tiktok.com/@hailzngrace/video/7514516374224489771?is_from_webapp=1&sender_device=pc&web_id=7529868947924829714 | D24: Messaged | F24: purelyaria | G24: https://vt.tiktok.com/ZSDAaEBCG/ | I24: Consented, Not Included | K24: michael.diconstanzo | L24: https://www.tiktok.com/@michael.dicostanzo/video/7374955868519157038?is_from_webapp=1&sender_device=pc&web_id=7534997804440471048 | M24: mdicostanzo@viralnationtalent.com | N24: Messaged | P24: mundospizzeria | Q24: https://vt.tiktok.com/ZSDRpgxbs/ | S24: Messaged | U24: il_leadership | V24: https://vt.tiktok.com/ZSDRbn7b1/ | X24: Messaged | Z24: brewdliciouscoffee | AA24: https://www.tiktok.com/@brewdliciouscoffee/video/7536292226394066189?is_from_webapp=1&sender_device=pc&web_id=7529868947924829714 | AC24: Messaged | AE24: mcd_creative | AF24: https://www.tiktok.com/@mcd_creative/video/7358768689556016401?is_from_webapp=1&sender_device=pc&web_id=7534997804440471048 | AH24: Messaged | AJ24: aqilahwf | AK24: https://vt.tiktok.com/ZSAvpcC4K/ | AM24: Consented | AO24: sara.durante5 | AP24: https://www.tiktok.com/@sara.durante5/video/7521136157501967621?is_from_webapp=1&sender_device=pc&web_id=7529868947924829714 | AR24: Messaged | AT24: _ameeong | AU24: https://www.tiktok.com/@_ameeong/video/7532529094261591314?is_from_webapp=1&sender_device=pc&web_id=7529868947924829714 | AW24: Messaged | AY24: imeldalyyy | AZ24: https://www.tiktok.com/@imeldalyyy/video/7510962544870280504?is_from_webapp=1&sender_device=pc&web_id=7529868947924829714 | BB24: Messaged | BD24: msdmickey135 | BE24: https://www.tiktok.com/@msdmickey135/video/7510590647372500255?is_from_webapp=1&sender_device=pc&web_id=7529858502199395858 | BF24: mikaelasdougherty@gmail.com | BG24: Consented, Not Included | BI24: julia.jo1 | BJ24: https://www.tiktok.com/@julia.jo1/video/6872061186486095109?is_from_webapp=1&sender_device=pc&web_id=7529868947924829714 | BL24: Messaged | BQ24: exchange gift challenge | BR24: =BL274 -> 10
A25: jadielane | B25: https://www.tiktok.com/@jadielane/video/7503338388653870382?is_from_webapp=1&sender_device=pc&web_id=7529868947924829714 | C25: Jadielanecollabs@gmail.com | D25: Messaged | F25: jassyyy.4 | G25: https://vt.tiktok.com/ZSDAmdv7S/ | I25: Messaged | K25: annaa.allisonn | L25: https://vt.tiktok.com/ZSAvQJ8Yw/ | M25: anondaeallison@gmail.com | N25: Messaged | P25: itssky0.0 | Q25: https://vt.tiktok.com/ZSDRpbrpg/ | S25: Consented, Not Included | U25: soocialhub | V25: https://vt.tiktok.com/ZSDRboVNc/ | X25: Messaged | Z25: dae.gee | AA25: https://www.tiktok.com/@dae.gee/video/7538842751920590110?is_from_webapp=1&sender_device=pc&web_id=7529868947924829714 | AC25: Messaged | AE25: ananotana | AF25: https://www.tiktok.com/@ananotana/video/7347499172737666347?is_from_webapp=1&sender_device=pc&web_id=7534997804440471048 | AH25: Messaged | AJ25: simp2257 | AK25: https://vt.tiktok.com/ZSAvpuy47/ | AL25: Unavailable | AM25: Consented | AO25: savt.aesthetics | AP25: https://www.tiktok.com/@savt.aesthetics/video/7469452316941290783?is_from_webapp=1&sender_device=pc&web_id=7529868947924829714 | AQ25: savtoddaesthetic@gmail.com | AR25: Messaged | AT25: dreaniks | AU25: https://www.tiktok.com/@dreaniks/video/7531330789850516754?lang=en | AW25: Consented, Not Included | AY25: commonmode | AZ25: https://www.tiktok.com/@commonmode/video/7518995607902489863?is_from_webapp=1&sender_device=pc&web_id=7529868947924829714 | BB25: Messaged | BD25: sramii2 | BE25: https://www.tiktok.com/@sramii2/video/7545608318652288270 | BG25: Messaged | BI25: themontestwins | BJ25: https://www.tiktok.com/@themontestwins/video/6903616059081788678?is_from_webapp=1&sender_device=pc&web_id=7529868947924829714 | BK25: montestwins@portraitmgmt.com | BL25: Messaged
A26: .kirsten0 | B26: https://www.tiktok.com/@.kirsten0/video/7423889587870780704?is_from_webapp=1&sender_device=pc&web_id=7529868947924829714 | D26: Messaged | F26: kykeyumz | G26: https://vt.tiktok.com/ZSDAmehYa/ | H26: NEW | I26: Consented | K26: mialmiranda | L26: https://vt.tiktok.com/ZSAvQ72vM/ | M26: mialovemiranda@gmail.com | N26: Messaged | P26: judyannlabticluna_on_ig | Q26: https://vt.tiktok.com/ZSDRsFWwM/ | S26: Consented, Not Included | U26: rhsfilipinoclub | V26: https://vt.tiktok.com/ZSDRgyWya/ | X26: Messaged | Z26: brewologyri | AA26: https://www.tiktok.com/@brewologyri/video/7545134730618899767?is_from_webapp=1&sender_device=pc&web_id=7529868947924829714 | AC26: Messaged | AE26: luxegen | AF26: https://www.tiktok.com/@luxegen/video/7350398632736116000?is_from_webapp=1&sender_device=pc&web_id=7534997804440471048 | AH26: Messaged | AJ26: pasang_lb | AK26: https://vt.tiktok.com/ZSAvpcqgh/ | AM26: Messaged | AO26: ebtihel_malik | AP26: https://www.tiktok.com/@ebtihel_malik/video/7478810853534403863?is_from_webapp=1&sender_device=pc&web_id=7529868947924829714 | AR26: Messaged | AT26: sophiajiaa | AU26: https://www.tiktok.com/@sophiajiaa/video/7534019039190912263?lang=en | AW26: Consented | AY26: kytchen_kravings | AZ26: https://www.tiktok.com/@kytchen_kravings/video/7513158312913915158?is_from_webapp=1&sender_device=pc&web_id=7529868947924829714 | BB26: Messaged | BD26: hollyybergyy | BE26: https://www.tiktok.com/@hollyybergyy/video/7540538612929056014 | BG26: Messaged | BI26: fairviewofficial | BJ26: https://www.tiktok.com/@fairviewofficial/video/6940055162392268038?is_from_webapp=1&sender_device=pc&web_id=7529868947924829714 | BL26: Messaged
A27: candiceeprr | B27: https://www.tiktok.com/@candiceeprr/video/7534789723420822786?is_from_webapp=1&sender_device=pc&web_id=7529868947924829714 | D27: Messaged | F27: dani__and__jo | G27: https://vt.tiktok.com/ZSDAa7uGv/ | I27: Messaged | K27: riisepeters | L27: https://vt.tiktok.com/ZSAvQK6Qd/ | M27: contact@riisepeters.com | N27: Messaged | P27: theguysfromyesterday | Q27: https://vt.tiktok.com/ZSDRsUcKR/ | S27: Consented | U27: gummy_rush | V27: https://vt.tiktok.com/ZSDRgjjuA/ | X27: Messaged | Z27: freshcupplayhouse | AA27: https://www.tiktok.com/@freshcupplayhouse/video/7548733446726618398?is_from_webapp=1&sender_device=pc&web_id=7529868947924829714 | AC27: Consented | AE27: _mira_mo | AF27: https://vt.tiktok.com/ZSAojf62h/ | AH27: Messaged | AJ27: simandoooo | AK27: https://vt.tiktok.com/ZSAvpw2a6/ | AM27: Messaged | AO27: heidilereng | AP27: https://www.tiktok.com/@heidilereng/video/7474242580524403970?is_from_webapp=1&sender_device=pc&web_id=7529868947924829714 | AR27: Messaged | AT27: desyaaaaaaaaaang | AU27: https://www.tiktok.com/@desyaaaaaaaaaang/video/7533657633388137735?lang=en | AW27: Messaged | AY27: notpariscottrell | AZ27: https://www.tiktok.com/@notpariscottrell/video/7506077979529710855?is_from_webapp=1&sender_device=pc&web_id=7529868947924829714 | BB27: Messaged | BD27: paulinebataller | BE27: https://www.tiktok.com/@paulinebataller/video/7474194344744865045 | BG27: Consented, Not Included | BI27: alyssarafael | BJ27: https://www.tiktok.com/@alyssarafael/video/6879245557534067974?is_from_webapp=1&sender_device=pc&web_id=7529868947924829714 | BK27: contact@alyssarafael.com | BL27: Messaged
A28: _claudiahamilton | B28: https://www.tiktok.com/@_claudiahamilton/video/7164887675156139269?is_from_webapp=1&sender_device=pc&web_id=7529868947924829714 | D28: Messaged | F28: kriiizhaaa | G28: https://vt.tiktok.com/ZSDAm8akn/ | I28: Consented | K28: kylee.grive | L28: https://vt.tiktok.com/ZSAvCFm42/ | M28: kyleegrive@gmail.com | N28: Messaged | P28: aznmc_ | Q28: https://vt.tiktok.com/ZSDRsLgDh/ | S28: Consented, Not Included | U28: bchs.hosa | V28: https://vt.tiktok.com/ZSDRgvBTJ/ | X28: Consented | Z28: cplrayscoffee | AA28: https://www.tiktok.com/@cplrayscoffee/video/7541907163074022669?is_from_webapp=1&sender_device=pc&web_id=7529868947924829714 | AC28: Messaged | AE28: laurabrookerxoxo | AF28: https://vt.tiktok.com/ZSAojX4Ps/ | AH28: Messaged | AJ28: yuehaaan | AK28: https://vt.tiktok.com/ZSAvpwJx2/ | AM28: Consented | AO28: violet_autumn_ | AP28: https://www.tiktok.com/@violet_autumn_/video/7466107890554719534?is_from_webapp=1&sender_device=pc&web_id=7529868947924829714 | AR28: Messaged | AT28: unica.hijaa | AU28: https://www.tiktok.com/@unica.hijaa/video/7541258684232420628?is_from_webapp=1&sender_device=pc&web_id=7529868947924829714 | AW28: Messaged | AY28: hannahong22 | AZ28: https://www.tiktok.com/@hannahong22/video/7517118935481797906?is_from_webapp=1&sender_device=pc&web_id=7529868947924829714 | BB28: Consented | BD28: mbsangels | BE28: https://www.tiktok.com/@mbsangels/video/7537753796995190038?is_from_webapp=1&sender_device=pc&web_id=7529858502199395858 | BF28: toriandelektramb@gmail.com | BG28: Messaged | BI28: sue.rose | BJ28: https://www.tiktok.com/@sue.rose/video/6880244813120195845?is_from_webapp=1&sender_device=pc&web_id=7529868947924829714 | BK28: suexjosh@gmail.com suerose@jakerosenentertainment.com | BL28: Messaged
A29: daileenjovet5 | B29: https://www.tiktok.com/@daileenjovet5/video/7459201329077030175?is_from_webapp=1&sender_device=pc&web_id=7529868947924829714 | D29: Messaged | F29: josie_spammin | G29: https://vt.tiktok.com/ZSDAmhhjG/ | I29: Messaged | K29: meglskalla | L29: https://vt.tiktok.com/ZSAvCAQKe/ | M29: team@jenniferpowell.com | N29: Messaged | P29: aub.says | Q29: https://vt.tiktok.com/ZSDRsBA8W/ | S29: Messaged | U29: arizonafireplaces | V29: https://vt.tiktok.com/ZSDRg4s47/ | X29: Messaged | Z29: wildberrysmoothieco | AA29: https://www.tiktok.com/@wildberrysmoothieco/video/7546269847013936415?is_from_webapp=1&sender_device=pc&web_id=7529868947924829714 | AC29: Messaged | AE29: salmaelboukili3 | AF29: https://vt.tiktok.com/ZSAojPTb2/ | AH29: Consented | AJ29: nanagmzz | AK29: https://vt.tiktok.com/ZSAvp39Cw/ | AM29: Messaged | AO29: giagracesmith | AP29: https://www.tiktok.com/@giagracesmith/video/7469751409668361494?is_from_webapp=1&sender_device=pc&web_id=7529868947924829714 | AR29: Consented | AT29: thisisafront | AU29: https://www.tiktok.com/@thisisafront/video/7540136220626586902?is_from_webapp=1&sender_device=pc&web_id=7529868947924829714 | AW29: Messaged | AY29: mawieri | AZ29: https://www.tiktok.com/@mawieri/video/7510178099716427026?is_from_webapp=1&sender_device=pc&web_id=7529868947924829714 | BB29: Messaged | BD29: typo_shop | BE29: https://www.tiktok.com/@typo_shop/video/7515300621927353617?is_from_webapp=1&sender_device=pc&web_id=7529868947924829714 | BG29: Messaged | BI29: kimetherton99 | BJ29: https://www.tiktok.com/@kimetherton99/video/6880242982054825222?is_from_webapp=1&sender_device=pc&web_id=7529868947924829714 | BK29: kimetherton99@gmail.com | BL29: Cannot message
A30: alottamayo | B30: https://www.tiktok.com/@alottamayo/video/7480372191985437994?is_from_webapp=1&sender_device=pc&web_id=7529868947924829714 | D30: Messaged | F30: jjentryyy | G30: https://vt.tiktok.com/ZSDAmrRJr/ | I30: Messaged | K30: adzxchance | L30: https://vt.tiktok.com/ZSAvCU8VN/ | N30: Messaged | P30: mark_marian15 | Q30: https://vt.tiktok.com/ZSDRsJ2FU/ | S30: Consented, Not Included | U30: cafemonaco.ph | V30: https://vt.tiktok.com/ZSDRpJXwL/ | X30: Messaged | Z30: poppys.sipanddrift | AA30: https://www.tiktok.com/@poppys.sipanddrift/video/7539596163926723854?is_from_webapp=1&sender_device=pc&web_id=7529868947924829714 | AC30: Messaged | AE30: oncampuspromotions | AF30: https://vt.tiktok.com/ZSAojXwkP/ | AH30: Messaged | AJ30: jennifer.antal | AK30: https://vt.tiktok.com/ZSAvpWr5x/ | AM30: Messaged | AO30: fabulatehq | AP30: https://www.tiktok.com/@fabulatehq/video/7480402418694491410?is_from_webapp=1&sender_device=pc&web_id=7529868947924829714 | AR30: Messaged | AT30: louiseanastasiaa | AU30: https://www.tiktok.com/@louiseanastasiaa/video/7528654023243631878?is_from_webapp=1&sender_device=pc&web_id=7529868947924829714 | AW30: Messaged | AY30: amysofiab | AZ30: https://www.tiktok.com/@amysofiab/video/7508760477703539970?is_from_webapp=1&sender_device=pc&web_id=7529868947924829714 | BB30: Messaged | BD30: alexandeunice | BE30: https://www.tiktok.com/@alexandeunice/video/7467234532798909703?is_from_webapp=1&sender_device=pc&web_id=7529868947924829714 | BF30: contact@mer-studios.com | BG30: Consented | BI30: juandchan | BJ30: https://www.tiktok.com/@juandchan/video/6880320042005777669?is_from_webapp=1&sender_device=pc&web_id=7529868947924829714 | BK30: juandchanco@gmail.com | BL30: Messaged
A31: lilybarnicott | B31: https://www.tiktok.com/@lilybarnicott/video/7537474367144463638?is_from_webapp=1&sender_device=pc&web_id=7529868947924829714 | D31: Did not consent | F31: aldriandeleon | G31: https://vt.tiktok.com/ZSDAmU79s/ | I31: Messaged | K31: ashlyn_bischoff | L31: https://vt.tiktok.com/ZSAvCCRXr/ | M31: ashlynb.business@gmail.com | N31: Messaged | P31: skylovemommy | Q31: https://vt.tiktok.com/ZSDRsgw6M/ | S31: Messaged | U31: yunnanbypotomac | V31: https://vt.tiktok.com/ZSDRgbHF6/ | X31: Messaged | Z31: carlosmexrestaurant | AA31: https://www.tiktok.com/@carlosmexrestaurant/video/7544513956912713015?is_from_webapp=1&sender_device=pc&web_id=7529868947924829714 | AC31: Messaged | AE31: lexxrexx_ | AF31: https://vt.tiktok.com/ZSAojhPuK/ | AH31: Messaged | AJ31: mariesavellano | AK31: https://vt.tiktok.com/ZSAvp3sWu/ | AM31: Messaged | AO31: caraasport | AP31: https://www.tiktok.com/@caraasport/video/7484374421122141483?is_from_webapp=1&sender_device=pc&web_id=7529868947924829714 | AR31: Messaged | AT31: whitlynetland | AU31: https://www.tiktok.com/@whitlynetland/video/7529144263129517343?is_from_webapp=1&sender_device=pc&web_id=7529868947924829714 | AW31: Messaged | AY31: sophiaisabel.yt | AZ31: https://www.tiktok.com/@sophiaisabel.yt/video/7519102183850151176?is_from_webapp=1&sender_device=pc&web_id=7529868947924829714 | BB31: Consented | BD31: ericafwu | BE31: https://www.tiktok.com/@ericafwu/video/7516619536284552491?is_from_webapp=1&sender_device=pc&web_id=7529868947924829714 | BF31: erica.wu@theviralistgroup.com | BG31: Consented | BI31: hunnaxlib | BJ31: https://www.tiktok.com/@hunnaxlib/video/6872116913602825477?is_from_webapp=1&sender_device=pc&web_id=7529868947924829714 | BK31: nick@grail-talent.com | BL31: Messaged
A32: grapegrapegrapeyyy | B32: https://www.tiktok.com/@grapegrapegrapeyyy/video/7455543826250206506?is_from_webapp=1&sender_device=pc&web_id=7529868947924829714 | C32: grapegrapegrapeyyy@gmail.com | D32: Messaged | F32: jasminecostley | G32: https://vt.tiktok.com/ZSDAmu8Yn/ | I32: Messaged | K32: allimaxfield | L32: https://vt.tiktok.com/ZSAvCf7hh/ | M32: allimaxfieldcollabs@gmail.com | N32: Messaged | P32: emereenichole | Q32: https://vt.tiktok.com/ZSDRscUF4/ | S32: Consented | U32: hmongstoutstudentorg | V32: https://vt.tiktok.com/ZSDRgvmqh/ | X32: Messaged | Z32: xapacoffee | AA32: https://www.tiktok.com/@xapacoffee/video/7548887299476475166?is_from_webapp=1&sender_device=pc&web_id=7529868947924829714 | AC32: Messaged | AE32: just_annaz | AF32: https://vt.tiktok.com/ZSAoj6LT3/ | AH32: Messaged | AJ32: amibipinlove | AK32: https://vt.tiktok.com/ZSAvpXW2G/ | AM32: Messaged | AO32: selina.shf | AP32: https://www.tiktok.com/@selina.shf/video/7470508950975237398?is_from_webapp=1&sender_device=pc&web_id=7529868947924829714 | AQ32: selina.shfcontact@gmail.com | AR32: Messaged | AT32: prtynicxs | AU32: https://www.tiktok.com/@prtynicxs/video/7544779195751091474?is_from_webapp=1&sender_device=pc&web_id=7529868947924829714 | AW32: Messaged | AY32: krismasr | AZ32: https://www.tiktok.com/@krismasr/video/7507483220401949998?is_from_webapp=1&sender_device=pc&web_id=7529868947924829714 | BB32: Messaged | BD32: paula.wagener | BE32: https://www.tiktok.com/@paula.wagener/video/7473061878034484502?is_from_webapp=1&sender_device=pc&web_id=7529868947924829714 | BG32: Messaged | BI32: rinispencer | BJ32: https://www.tiktok.com/@rinispencer/video/6928941076367674629?is_from_webapp=1&sender_device=pc&web_id=7529868947924829714 | BL32: Messaged
A33: ashleeyyyy.x | B33: https://www.tiktok.com/@ashleeyyyy.x/video/7512188715108732182?is_from_webapp=1&sender_device=pc&web_id=7529868947924829714 | D33: Messaged | F33: yourgurlyana | G33: https://vt.tiktok.com/ZSDAmfMYm/ | I33: Consented, Not Included | K33: carlyminnick | L33: https://vt.tiktok.com/ZSAvCQvRT/ | M33: carlyminnick@comcast.net | N33: Consented | P33: _jessiecarr | Q33: https://vt.tiktok.com/ZSDYE6FPc/ | S33: Messaged | U33: laura.canada | V33: https://vt.tiktok.com/ZSDRpR5Ew/ | X33: Consented | Z33: pollencafeandicecream | AA33: https://www.tiktok.com/@pollencafeandicecream/video/7547140126825073933?is_from_webapp=1&sender_device=pc&web_id=7529868947924829714 | AC33: Messaged | AE33: gracierigsby | AF33: https://vt.tiktok.com/ZSAojSXWL/ | AH33: Messaged | AJ33: jimanj0 | AK33: https://vt.tiktok.com/ZSAvs162B/ | AM33: Messaged | AO33: eastgateness | AP33: https://www.tiktok.com/@eastgateness/video/7507251228879981846?is_from_webapp=1&sender_device=pc&web_id=7529868947924829714 | AR33: Messaged | AT33: evriiiiil | AU33: https://www.tiktok.com/@evriiiiil/video/7545284733018574098?is_from_webapp=1&sender_device=pc&web_id=7529868947924829714 | AW33: Messaged | AY33: gcsuico | AZ33: https://www.tiktok.com/@gcsuico/video/7510964090185993492?is_from_webapp=1&sender_device=pc&web_id=7529868947924829714 | BB33: Consented | BD33: sunnyside.northampton | BE33: https://www.tiktok.com/@sunnyside.northampton/video/7539905279681367318?is_from_webapp=1&sender_device=pc&web_id=7529868947924829714 | BG33: Cannot message | BI33: parkerehenry7 | BJ33: https://www.tiktok.com/@parkerehenry7/video/6885891850096413958?is_from_webapp=1&sender_device=pc&web_id=7529868947924829714 | BL33: Messaged
A34: soapsterr | B34: https://www.tiktok.com/@soapsterr/video/7475501954366688558?is_from_webapp=1&sender_device=pc&web_id=7529868947924829714 | C34: swynng29@gmail.com | D34: Messaged | F34: ggeoxn | G34: https://vt.tiktok.com/ZSDAmCBYg/ | I34: Messaged | K34: thelullabyclub | L34: https://vt.tiktok.com/ZSAvCM911/ | N34: Messaged | P34: tongbin08 | Q34: https://vt.tiktok.com/ZSDYEdCMW/ | S34: Messaged | U34: thejudgegroup | V34: https://vt.tiktok.com/ZSDRpS8YL/ | X34: Messaged | Z34: tcc.magnolia | AA34: https://www.tiktok.com/@tcc.magnolia/video/7533673734629002527?is_from_webapp=1&sender_device=pc&web_id=7529868947924829714 | AC34: Messaged | AE34: tra.ciey | AF34: https://vt.tiktok.com/ZSAojxbFL/ | AH34: Messaged | AJ34: raquelvillagran | AK34: https://vt.tiktok.com/ZSAvsUWXC/ | AM34: Messaged | AO34: cosmetify | AP34: https://www.tiktok.com/@cosmetify/video/7471320711651691778?is_from_webapp=1&sender_device=pc&web_id=7529868947924829714 | AR34: Consented | AT34: eilidhstiktoke | AU34: https://www.tiktok.com/@eilidhstiktoke/video/7544369832804781334?is_from_webapp=1&sender_device=pc&web_id=7529868947924829714 | AW34: Messaged | AY34: heliotroniq | AZ34: https://www.tiktok.com/@heliotroniq/video/7514317387538156821?is_from_webapp=1&sender_device=pc&web_id=7529868947924829714 | BB34: Consented, Not Included | BD34: centralpub | BE34: https://www.tiktok.com/@centralpub/video/7548220492784717111?is_from_webapp=1&sender_device=pc&web_id=7529868947924829714 | BG34: Messaged | BI34: its.namess | BJ34: https://www.tiktok.com/@its.namess/video/6920522122670460161?is_from_webapp=1&sender_device=pc&web_id=7529868947924829714 | BL34: Messaged
A35: all.hail.ash | B35: https://www.tiktok.com/@all.hail.ash/video/7497404044869176618?is_from_webapp=1&sender_device=pc&web_id=7529868947924829714 | D35: Messaged | F35: angeel.nh | G35: https://vt.tiktok.com/ZSDAmsRDx/ | I35: Messaged | K35: hallieandmaddi | L35: https://vt.tiktok.com/ZSAvChqAJ/ | M35: hallieandmaddi@thisisamplify.com | N35: Messaged | P35: itsnicoleanne | Q35: https://vt.tiktok.com/ZSDYE6UeL/ | S35: Messaged | U35: gmbcc_ugm | V35: https://vt.tiktok.com/ZSDRp5tvH/ | X35: Messaged | Z35: chipley.nutrition | AA35: https://www.tiktok.com/@chipley.nutrition/video/7538899491726937358?is_from_webapp=1&sender_device=pc&web_id=7529868947924829714 | AC35: Messaged | AE35: coconuthead1301 | AF35: https://vt.tiktok.com/ZSAoj6fP2/ | AH35: Messaged | AJ35: naurah.alatas | AK35: https://vt.tiktok.com/ZSAvsB7cp/ | AM35: Messaged | AO35: crochetlin | AP35: https://www.tiktok.com/@crochetlin/video/7537654349737053462?is_from_webapp=1&sender_device=pc&web_id=7529868947924829714 | AR35: Messaged | AT35: alennamariz | AU35: https://www.tiktok.com/@alennamariz/video/7540694502915181842?is_from_webapp=1&sender_device=pc&web_id=7529868947924829714 | AW35: Consented | AY35: ungkuhanimm | AZ35: https://www.tiktok.com/@ungkuhanimm/video/7534748773285727495?is_from_webapp=1&sender_device=pc&web_id=7529868947924829714 | BB35: Messaged | BD35: giuliana.kyla_spam | BE35: https://www.tiktok.com/@giuliana.kyla_spam/video/7462164980066995487?is_from_webapp=1&sender_device=pc&web_id=7529868947924829714 | BG35: Messaged | BI35: makenziedawn | BJ35: https://www.tiktok.com/@makenziedawn/video/6929281274448284934?is_from_webapp=1&sender_device=pc&web_id=7529868947924829714 | BL35: Messaged
